Workbook

Sheet 안내
A1: 이사벨 반 모의고사·내신 성적 분석
A2: Metta 영어 전문학원 · 성적표 사진(2020–2026)에서 옮긴 자료
A4: 시트 구성
A5: · 반 비교: 세 반을 같은 단계(중1 첫 시험, 첫 고2 모의고사 등)에서 비교
A6: · 김건희반_2020: 2020 중1 상위 4명, 중1~중3 (2020–2022), 중3 내신
A7: · 구성관반_2023: 2023 중1 반 4명, 중1~중3 3차 고3 (2023–2025), 중1~중3 내신
A8: · 이서연반_2025: 2025 중1 반 중 2026년까지 다닌 6명, 중1 1~4차 + 중2 1~3차, 중1·중2 내신
A10: 읽는 법
A11: · 파란 글씨: 성적표에서 옮긴 값 (수정 가능) · 검은 글씨: 계산식 · 초록 글씨: 다른 시트에서 가져온 값
A12: · 듣기 17문항, 독해 28문항 기준 맞은 개수. 총점 100점, 절대평가 등급(90점 이상 1등급, 10점 단위)
A13: · 빈칸은 성적표에 기록이 없거나 미응시. 메모(빨간 삼각형)에 이유를 적어 두었습니다.
A15: 참고
... A19: · 구성관반 김의현·최리원(2023 1차만 응시), 백시우·신상훈(2025 합류)은 제외했습니다.

Sheet 반 비교
A1: 반별 같은 단계 비교 (평균)
A2: 초록 글씨 = 각 반 시트의 평균 행을 가져온 값. 중2 3차는 세 반 모두 처음 본 고2 모의고사입니다.
A4: 총점 평균 | B4: 2020 김건희 반 | C4: 2023 구성관 반 | D4: 2025 이서연 반
A5: 중1 첫 시험 (고1) | B5: =김건희반_2020!B10 -> 62.75 | C5: =구성관반_2023!B10 -> 67 | D5: =이서연반_2025!B12 -> 65
A6: 중1 마지막 시험 | B6: =김건희반_2020!F10 -> 78.5 | C6: =구성관반_2023!F10 -> 81.75 | D6: =이서연반_2025!E12 -> 81.333333
A7: 중2 첫 시험 | B7: =김건희반_2020!G10 -> 79 | C7: =구성관반_2023!G10 -> 94.5 | D7: =이서연반_2025!F12 -> 79
A8: 첫 고2 모의고사 (중2 3차) | B8: =김건희반_2020!I10 -> 83.25 | C8: =구성관반_2023!I10 -> 86 | D8: =이서연반_2025!H12 -> 81.166667
A9: 가장 최근 시험 | B9: =김건희반_2020!N10 -> 87.666667 | C9: =구성관반_2023!M10 -> 92.25 | D9: =이서연반_2025!H12 -> 81.166667
A10: 중1 첫 시험 → 첫 고2 모의고사 변화 | B10: =B8-B5 -> 20.5 | C10: =C8-C5 -> 19 | D10: =D8-D5 -> 16.166667
A12: 독해 평균 (맞은 개수) | B12: 2020 김건희 반 | C12: 2023 구성관 반 | D12: 2025 이서연 반
A13: 중1 첫 시험 (고1) | B13: =김건희반_2020!B33 | C13: =구성관반_2023!B33 -> 14.75 | D13: =이서연반_2025!B41 -> 15
A14: 중1 마지막 시험 | B14: =김건희반_2020!F33 -> 19.25 | C14: =구성관반_2023!F33 -> 20.75 | D14: =이서연반_2025!E41 -> 21
A15: 중2 첫 시험 | B15: =김건희반_2020!G33 -> 19.75 | C15: =구성관반_2023!G33 -> 25.75 | D15: =이서연반_2025!F41 -> 20.166667
A16: 첫 고2 모의고사 (중2 3차) | B16: =김건희반_2020!I33 -> 21.75 | C16: =구성관반_2023!I33 -> 23.25 | D16: =이서연반_2025!H41 -> 20.666667
A17: 가장 최근 시험 | B17: =김건희반_2020!N33 -> 23 | C17: =구성관반_2023!M33 -> 24.75 | D17: =이서연반_2025!H41 -> 20.666667

Sheet 김건희반_2020
A1: 2020 중1 반 (김건희 반) · 모의고사 성적 (2020–2022)
A2: 반: 1M-A → 2M-A → 3M-A · 파란 글씨 = 성적표 사진에서 옮긴 입력값, 검은 글씨 = 계산식. 빈칸 = 기록 없음/미응시.
A4: 총점
A5: 학생 | B5: 중1 1차 고1 | C5: 중1 2차 고1 | D5: 중1 3차 고1 | E5: 중1 4차 고1 | F5: 중1 5차 고1 | G5: 중2 1차 모의고사 | H5: 중2 2차 모의고사 | I5: 중2 3차 고2 | J5: 중2 4차 고2 | K5: 중3 1차 고2 | L5: 중3 2차 고2 | M5: 중3 3차 고3 | N5: 중3 4차 수능 | O5: 첫 시험 | P5: 마지막 시험 | Q5: 변화 | R5: 최고
A6: 김건희 | B6: 69 | C6: 75 | D6: 76 | E6: 90 | F6: 73 | G6: 82 | H6: 95 | I6: 87 | J6: 86 | K6: 80 | L6: 84 | M6: 86 | N6: 88 | O6: =B6 -> 69 | P6: =LOOKUP(9.99E+307,B6:N6) -> 88 | Q6: =P6-O6 -> 19 | R6: =MAX(B6:N6) -> 95
A7: 안도후 | B7: 67 | C7: 66 | D7: 72 | E7: 81 | F7: 84 | G7: 83 | H7: 93 | I7: 82 | J7: 77 | K7: 79 | L7: 80 | M7: 88 | N7: 88 | O7: =B7 -> 67 | P7: =LOOKUP(9.99E+307,B7:N7) -> 88 | Q7: =P7-O7 -> 21 | R7: =MAX(B7:N7) -> 93
A8: 안동휘 | B8: 58 | C8: 73 | D8: 75 | E8: 78 | F8: 77 | G8: 77 | H8: 90 | I8: 80 | J8: 81 | K8: 91 | L8: 87 | M8: 93 | N8: 87 | O8: =B8 -> 58 | P8: =LOOKUP(9.99E+307,B8:N8) -> 87 | Q8: =P8-O8 -> 29 | R8: =MAX(B8:N8) -> 93
A9: 나민하 | B9: 57 | C9: 79 | D9: 76 | E9: 71 | F9: 80 | G9: 74 | H9: 87 | I9: 84 | J9: 89 | K9: 74 | L9: 86 | M9: 74 | O9: =B9 -> 57 | P9: =LOOKUP(9.99E+307,B9:N9) -> 74 | Q9: =P9-O9 -> 17 | R9: =MAX(B9:N9) -> 89
A10: 평균 | B10: =IF(COUNT(B6:B9)=0,"",AVERAGE(B6:B9)) -> 62.75 | C10: =IF(COUNT(C6:C9)=0,"",AVERAGE(C6:C9)) -> 73.25 | D10: =IF(COUNT(D6:D9)=0,"",AVERAGE(D6:D9)) -> 74.75 | E10: =IF(COUNT(E6:E9)=0,"",AVERAGE(E6:E9)) -> 80 | F10: =IF(COUNT(F6:F9)=0,"",AVERAGE(F6:F9)) -> 78.5 | G10: =IF(COUNT(G6:G9)=0,"",AVERAGE(G6:G9)) -> 79 | H10: =IF(COUNT(H6:H9)=0,"",AVERAGE(H6:H9)) -> 91.25 | I10: =IF(COUNT(I6:I9)=0,"",AVERAGE(I6:I9)) -> 83.25 | ... N10: =IF(COUNT(N6:N9)=0,"",AVERAGE(N6:N9)) -> 87.666667
A12: 등급
A13: 학생 | B13: 중1 1차 고1 | C13: 중1 2차 고1 | D13: 중1 3차 고1 | E13: 중1 4차 고1 | F13: 중1 5차 고1 | G13: 중2 1차 모의고사 | H13: 중2 2차 모의고사 | I13: 중2 3차 고2 | J13: 중2 4차 고2 | K13: 중3 1차 고2 | L13: 중3 2차 고2 | M13: 중3 3차 고3 | N13: 중3 4차 수능
A14: 김건희 | B14: 4 | C14: 3 | D14: 3 | E14: 1 | F14: 3 | G14: 2 | H14: 1 | I14: 2 | J14: 2 | K14: 2 | L14: 2 | M14: 2 | N14: 2
A15: 안도후 | B15: 4 | C15: 4 | D15: 3 | E15: 2 | F15: 2 | G15: 2 | H15: 1 | I15: 2 | J15: 3 | K15: 3 | L15: 2 | M15: 2 | N15: 2
A16: 안동휘 | B16: 5 | C16: 3 | D16: 3 | E16: 3 | F16: 3 | G16: 3 | H16: 1 | I16: 2 | J16: 2 | K16: 1 | L16: 2 | M16: 1 | N16: 2
A17: 나민하 | B17: 5 | C17: 3 | D17: 3 | E17: 3 | F17: 2 | G17: 3 | H17: 2 | I17: 2 | J17: 2 | K17: 3 | L17: 2 | M17: 3
A19: 듣기 (맞은 개수 / 17)
A20: 학생 | B20: 중1 1차 고1 | C20: 중1 2차 고1 | D20: 중1 3차 고1 | E20: 중1 4차 고1 | F20: 중1 5차 고1 | G20: 중2 1차 모의고사 | H20: 중2 2차 모의고사 | I20: 중2 3차 고2 | J20: 중2 4차 고2 | K20: 중3 1차 고2 | L20: 중3 2차 고2 | M20: 중3 3차 고3 | N20: 중3 4차 수능
A21: 김건희 | C21: 16 | D21: 17 | E21: 17 | F21: 16 | G21: 17 | H21: 17 | I21: 17 | J21: 16 | K21: 16 | L21: 17 | M21: 17 | N21: 17
A22: 안도후 | C22: 15 | D22: 16 | E22: 17 | F22: 17 | G22: 17 | H22: 17 | I22: 17 | J22: 17 | K22: 17 | L22: 17 | M22: 17 | N22: 17
A23: 안동휘 | C23: 17 | D23: 17 | E23: 17 | F23: 16 | G23: 17 | H23: 17 | I23: 17 | J23: 17 | K23: 17 | L23: 17 | M23: 17 | N23: 17
A24: 나민하 | C24: 16 | D24: 17 | E24: 15 | F24: 17 | G24: 16 | H24: 16 | I24: 16 | J24: 17 | K24: 14 | L24: 16 | M24: 16
A25: 평균 | B25: =IF(COUNT(B21:B24)=0,"",AVERAGE(B21:B24)) | C25: =IF(COUNT(C21:C24)=0,"",AVERAGE(C21:C24)) -> 16 | D25: =IF(COUNT(D21:D24)=0,"",AVERAGE(D21:D24)) -> 16.75 | E25: =IF(COUNT(E21:E24)=0,"",AVERAGE(E21:E24)) -> 16.5 | F25: =IF(COUNT(F21:F24)=0,"",AVERAGE(F21:F24)) -> 16.5 | G25: =IF(COUNT(G21:G24)=0,"",AVERAGE(G21:G24)) -> 16.75 | H25: =IF(COUNT(H21:H24)=0,"",AVERAGE(H21:H24)) -> 16.75 | I25: =IF(COUNT(I21:I24)=0,"",AVERAGE(I21:I24)) -> 16.75 | ... N25: =IF(COUNT(N21:N24)=0,"",AVERAGE(N21:N24)) -> 17
A27: 독해 (맞은 개수 / 28)
A28: 학생 | B28: 중1 1차 고1 | C28: 중1 2차 고1 | D28: 중1 3차 고1 | E28: 중1 4차 고1 | F28: 중1 5차 고1 | G28: 중2 1차 모의고사 | H28: 중2 2차 모의고사 | I28: 중2 3차 고2 | J28: 중2 4차 고2 | K28: 중3 1차 고2 | L28: 중3 2차 고2 | M28: 중3 3차 고3 | N28: 중3 4차 수능
A29: 김건희 | C29: 18 | D29: 19 | E29: 24 | F29: 18 | G29: 21 | H29: 26 | I29: 23 | J29: 23 | K29: 20 | L29: 21 | M29: 23 | N29: 23
A30: 안도후 | C30: 16 | D30: 18 | E30: 20 | F30: 21 | G30: 21 | H30: 25 | I30: 21 | J30: 19 | K30: 19 | L30: 20 | M30: 23 | N30: 23
A31: 안동휘 | C31: 16 | D31: 18 | E31: 18 | F31: 19 | G31: 19 | H31: 24 | I31: 20 | J31: 20 | K31: 24 | L31: 23 | M31: 25 | N31: 23
A32: 나민하 | C32: 20 | D32: 18 | E32: 17 | F32: 19 | G32: 18 | H32: 23 | I32: 23 | J32: 24 | K32: 20 | L32: 23 | M32: 18
A33: 평균 | B33: =IF(COUNT(B29:B32)=0,"",AVERAGE(B29:B32)) | C33: =IF(COUNT(C29:C32)=0,"",AVERAGE(C29:C32)) -> 17.5 | D33: =IF(COUNT(D29:D32)=0,"",AVERAGE(D29:D32)) -> 18.25 | E33: =IF(COUNT(E29:E32)=0,"",AVERAGE(E29:E32)) -> 19.75 | F33: =IF(COUNT(F29:F32)=0,"",AVERAGE(F29:F32)) -> 19.25 | G33: =IF(COUNT(G29:G32)=0,"",AVERAGE(G29:G32)) -> 19.75 | H33: =IF(COUNT(H29:H32)=0,"",AVERAGE(H29:H32)) -> 24.5 | I33: =IF(COUNT(I29:I32)=0,"",AVERAGE(I29:I32)) -> 21.75 | ... N33: =IF(COUNT(N29:N32)=0,"",AVERAGE(N29:N32)) -> 23
A35: 학교 내신 (영어)
A36: 학생 | B36: 중3 (2022) 1학기 중간 | C36: 중3 (2022) 1학기 기말 | D36: 중3 (2022) 2학기 중간 | E36: 중3 (2022) 2학기 기말 | F36: 평균
A37: 김건희 | B37: 100 | C37: 99 | D37: 96 | E37: 95 | F37: =IF(COUNT(B37:E37)=0,"",AVERAGE(B37:E37)) -> 97.5
A38: 안도후 | B38: 97 | C38: 98 | D38: 100 | E38: 100 | F38: =IF(COUNT(B38:E38)=0,"",AVERAGE(B38:E38)) -> 98.75
A39: 안동휘 | B39: 87 | C39: 99 | D39: 100 | E39: 98 | F39: =IF(COUNT(B39:E39)=0,"",AVERAGE(B39:E39)) -> 96
A40: 나민하 | B40: 96 | C40: 96 | D40: 94 | F40: =IF(COUNT(B40:E40)=0,"",AVERAGE(B40:E40)) -> 95.333333

Sheet 구성관반_2023
A1: 2023 중1 반 (구성관 반) · 모의고사 성적 (2023–2025)
A2: 반: 1M-S → 2M-S → 3M-S · 파란 글씨 = 성적표 사진에서 옮긴 입력값, 검은 글씨 = 계산식. 빈칸 = 기록 없음/미응시.
A4: 총점
A5: 학생 | B5: 중1 1차 고1 | C5: 중1 2차 고1 | D5: 중1 3차 고1 | E5: 중1 4차 고1 | F5: 중1 5차 고1 | G5: 중2 1차 고1 | H5: 중2 2차 고1 | I5: 중2 3차 고2 | J5: 중2 4차 고2 | K5: 중3 1차 고2 | L5: 중3 2차 고2 | M5: 중3 3차 고3 | N5: 첫 시험 | O5: 마지막 시험 | P5: 변화 | Q5: 최고
A6: 구성관 | B6: 71 | C6: 72 | D6: 73 | E6: 83 | F6: 83 | G6: 96 | H6: 97 | I6: 89 | J6: 100 | K6: 95 | L6: 92 | M6: 100 | N6: =B6 -> 71 | O6: =LOOKUP(9.99E+307,B6:M6) -> 100 | P6: =O6-N6 -> 29 | Q6: =MAX(B6:M6) -> 100
A7: 송지효 | B7: 58 | C7: 81 | D7: 81 | E7: 92 | F7: 94 | G7: 100 | H7: 94 | I7: 92 | J7: 84 | K7: 95 | L7: 95 | M7: 100 | N7: =B7 -> 58 | O7: =LOOKUP(9.99E+307,B7:M7) -> 100 | P7: =O7-N7 -> 42 | Q7: =MAX(B7:M7) -> 100
A8: 신준섭 | B8: 70 | C8: 74 | D8: 70 | E8: 75 | F8: 75 | G8: 90 | H8: 79 | I8: 94 | J8: 77 | K8: 89 | L8: 74 | M8: 87 | N8: =B8 -> 70 | O8: =LOOKUP(9.99E+307,B8:M8) -> 87 | P8: =O8-N8 -> 17 | Q8: =MAX(B8:M8) -> 94
A9: 박주연 | B9: 69 | C9: 65 | D9: 71 | E9: 84 | F9: 75 | G9: 92 | H9: 86 | I9: 69 | J9: 70 | K9: 89 | L9: 85 | M9: 82 | N9: =B9 -> 69 | O9: =LOOKUP(9.99E+307,B9:M9) -> 82 | P9: =O9-N9 -> 13 | Q9: =MAX(B9:M9) -> 92
A10: 평균 | B10: =IF(COUNT(B6:B9)=0,"",AVERAGE(B6:B9)) -> 67 | C10: =IF(COUNT(C6:C9)=0,"",AVERAGE(C6:C9)) -> 73 | D10: =IF(COUNT(D6:D9)=0,"",AVERAGE(D6:D9)) -> 73.75 | E10: =IF(COUNT(E6:E9)=0,"",AVERAGE(E6:E9)) -> 83.5 | F10: =IF(COUNT(F6:F9)=0,"",AVERAGE(F6:F9)) -> 81.75 | G10: =IF(COUNT(G6:G9)=0,"",AVERAGE(G6:G9)) -> 94.5 | H10: =IF(COUNT(H6:H9)=0,"",AVERAGE(H6:H9)) -> 89 | I10: =IF(COUNT(I6:I9)=0,"",AVERAGE(I6:I9)) -> 86 | ... M10: =IF(COUNT(M6:M9)=0,"",AVERAGE(M6:M9)) -> 92.25
A12: 등급
A13: 학생 | B13: 중1 1차 고1 | C13: 중1 2차 고1 | D13: 중1 3차 고1 | E13: 중1 4차 고1 | F13: 중1 5차 고1 | G13: 중2 1차 고1 | H13: 중2 2차 고1 | I13: 중2 3차 고2 | J13: 중2 4차 고2 | K13: 중3 1차 고2 | L13: 중3 2차 고2 | M13: 중3 3차 고3
A14: 구성관 | B14: 3 | C14: 3 | D14: 3 | E14: 2 | F14: 2 | G14: 1 | H14: 1 | I14: 2 | J14: 1 | K14: 1 | L14: 1 | M14: 1
A15: 송지효 | B15: 5 | C15: 2 | D15: 2 | E15: 1 | F15: 1 | G15: 1 | H15: 1 | I15: 1 | J15: 2 | K15: 1 | L15: 1 | M15: 1
A16: 신준섭 | B16: 3 | C16: 3 | D16: 3 | E16: 3 | F16: 3 | G16: 1 | H16: 3 | I16: 1 | J16: 3 | K16: 2 | L16: 3 | M16: 2
A17: 박주연 | B17: 4 | C17: 4 | D17: 3 | E17: 2 | F17: 3 | G17: 1 | H17: 2 | I17: 4 | J17: 3 | K17: 2 | L17: 2 | M17: 2
A19: 듣기 (맞은 개수 / 17)
A20: 학생 | B20: 중1 1차 고1 | C20: 중1 2차 고1 | D20: 중1 3차 고1 | E20: 중1 4차 고1 | F20: 중1 5차 고1 | G20: 중2 1차 고1 | H20: 중2 2차 고1 | I20: 중2 3차 고2 | J20: 중2 4차 고2 | K20: 중3 1차 고2 | L20: 중3 2차 고2 | M20: 중3 3차 고3
A21: 구성관 | B21: 17 | C21: 17 | D21: 16 | E21: 17 | F21: 17 | G21: 17 | H21: 17 | I21: 16 | J21: 17 | K21: 17 | L21: 16 | M21: 17
A22: 송지효 | B22: 15 | C22: 17 | D22: 17 | E22: 17 | F22: 17 | G22: 17 | H22: 17 | I22: 17 | J22: 17 | K22: 17 | L22: 17 | M22: 17
A23: 신준섭 | B23: 16 | C23: 16 | D23: 17 | E23: 17 | F23: 17 | G23: 17 | H23: 17 | I23: 17 | J23: 17 | K23: 17 | L23: 17 | M23: 17
A24: 박주연 | B24: 17 | C24: 16 | D24: 16 | E24: 17 | F24: 17 | G24: 17 | H24: 17 | I24: 16 | J24: 15 | K24: 17 | L24: 16 | M24: 17
A25: 평균 | B25: =IF(COUNT(B21:B24)=0,"",AVERAGE(B21:B24)) -> 16.25 | C25: =IF(COUNT(C21:C24)=0,"",AVERAGE(C21:C24)) -> 16.5 | D25: =IF(COUNT(D21:D24)=0,"",AVERAGE(D21:D24)) -> 16.5 | E25: =IF(COUNT(E21:E24)=0,"",AVERAGE(E21:E24)) -> 17 | F25: =IF(COUNT(F21:F24)=0,"",AVERAGE(F21:F24)) -> 17 | G25: =IF(COUNT(G21:G24)=0,"",AVERAGE(G21:G24)) -> 17 | H25: =IF(COUNT(H21:H24)=0,"",AVERAGE(H21:H24)) -> 17 | I25: =IF(COUNT(I21:I24)=0,"",AVERAGE(I21:I24)) -> 16.5 | ... M25: =IF(COUNT(M21:M24)=0,"",AVERAGE(M21:M24)) -> 17
A27: 독해 (맞은 개수 / 28)
A28: 학생 | B28: 중1 1차 고1 | C28: 중1 2차 고1 | D28: 중1 3차 고1 | E28: 중1 4차 고1 | F28: 중1 5차 고1 | G28: 중2 1차 고1 | H28: 중2 2차 고1 | I28: 중2 3차 고2 | J28: 중2 4차 고2 | K28: 중3 1차 고2 | L28: 중3 2차 고2 | M28: 중3 3차 고3
A29: 구성관 | B29: 16 | C29: 16 | D29: 18 | E29: 21 | F29: 21 | G29: 26 | H29: 27 | I29: 25 | J29: 28 | K29: 26 | L29: 26 | M29: 28
A30: 송지효 | B30: 12 | C30: 20 | D30: 21 | E30: 25 | F30: 26 | G30: 28 | H30: 26 | I30: 25 | J30: 22 | K30: 26 | L30: 26 | M30: 28
A31: 신준섭 | B31: 16 | C31: 17 | D31: 16 | E31: 17 | F31: 18 | G31: 24 | H31: 20 | I31: 26 | J31: 19 | K31: 23 | L31: 17 | M31: 23
A32: 박주연 | B32: 15 | C32: 15 | D32: 17 | E32: 21 | F32: 18 | G32: 25 | H32: 22 | I32: 17 | J32: 18 | K32: 24 | L32: 23 | M32: 20
A33: 평균 | B33: =IF(COUNT(B29:B32)=0,"",AVERAGE(B29:B32)) -> 14.75 | C33: =IF(COUNT(C29:C32)=0,"",AVERAGE(C29:C32)) -> 17 | D33: =IF(COUNT(D29:D32)=0,"",AVERAGE(D29:D32)) -> 18 | E33: =IF(COUNT(E29:E32)=0,"",AVERAGE(E29:E32)) -> 21 | F33: =IF(COUNT(F29:F32)=0,"",AVERAGE(F29:F32)) -> 20.75 | G33: =IF(COUNT(G29:G32)=0,"",AVERAGE(G29:G32)) -> 25.75 | H33: =IF(COUNT(H29:H32)=0,"",AVERAGE(H29:H32)) -> 23.75 | I33: =IF(COUNT(I29:I32)=0,"",AVERAGE(I29:I32)) -> 23.25 | ... M33: =IF(COUNT(M29:M32)=0,"",AVERAGE(M29:M32)) -> 24.75
A35: 학교 내신 (영어)
A36: 학생 | B36: 중3 (2025) 1학기 중간 | C36: 중3 (2025) 1학기 기말 | D36: 중3 (2025) 2학기 중간 | E36: 중1 (2023) 중간 | F36: 중1 (2023) 기말 | G36: 중2 (2024) 기말 | H36: 평균
A37: 구성관 | B37: 100 | C37: 100 | D37: 100 | E37: 100 | F37: 100 | G37: 100 | H37: =IF(COUNT(B37:G37)=0,"",AVERAGE(B37:G37)) -> 100
A38: 송지효 | B38: 98 | C38: 100 | D38: 100 | E38: 100 | F38: 100 | G38: 100 | H38: =IF(COUNT(B38:G38)=0,"",AVERAGE(B38:G38)) -> 99.666667
A39: 신준섭 | B39: 95 | C39: 95 | D39: 90 | E39: 100 | F39: 96 | G39: 98 | H39: =IF(COUNT(B39:G39)=0,"",AVERAGE(B39:G39)) -> 95.666667
A40: 박주연 | B40: 99 | C40: 96 | D40: 89 | E40: 95 | F40: 98 | G40: 99 | H40: =IF(COUNT(B40:G40)=0,"",AVERAGE(B40:G40)) -> 96

Sheet 이서연반_2025
A1: 2025 중1 반 (이서연 반) · 모의고사 성적 (2025–2026)
A2: 반: 1M-A → 2M-A · 파란 글씨 = 성적표 사진에서 옮긴 입력값, 검은 글씨 = 계산식. 빈칸 = 기록 없음/미응시.
A4: 총점
A5: 학생 | B5: 중1 1차 고1 | C5: 중1 2차 고1 | D5: 중1 3차 고1 | E5: 중1 4차 고1 | F5: 중2 1차 고1 | G5: 중2 2차 고1 | H5: 중2 3차 고2 | I5: 첫 시험 | J5: 마지막 시험 | K5: 변화 | L5: 최고
A6: 김지수 | B6: 63 | C6: 67 | D6: 68 | E6: 61 | F6: 66 | G6: 75 | H6: 77 | I6: =B6 -> 63 | J6: =LOOKUP(9.99E+307,B6:H6) -> 77 | K6: =J6-I6 -> 14 | L6: =MAX(B6:H6) -> 77
A7: 김채율 | B7: 59 | C7: 86 | D7: 76 | E7: 78 | F7: 87 | G7: 73 | H7: 76 | I7: =B7 -> 59 | J7: =LOOKUP(9.99E+307,B7:H7) -> 76 | K7: =J7-I7 -> 17 | L7: =MAX(B7:H7) -> 87
A8: 이서연 | B8: 88 | C8: 94 | D8: 91 | E8: 94 | F8: 87 | G8: 100 | H8: 95 | I8: =B8 -> 88 | J8: =LOOKUP(9.99E+307,B8:H8) -> 95 | K8: =J8-I8 -> 7 | L8: =MAX(B8:H8) -> 100
A9: 황재성 | B9: 67 | C9: 74 | D9: 71 | E9: 91 | F9: 88 | G9: 74 | H9: 82 | I9: =B9 -> 67 | J9: =LOOKUP(9.99E+307,B9:H9) -> 82 | K9: =J9-I9 -> 15 | L9: =MAX(B9:H9) -> 91
A10: 서예준 | B10: 51 | C10: 57 | D10: 68 | E10: 86 | F10: 73 | G10: 82 | H10: 80 | I10: =B10 -> 51 | J10: =LOOKUP(9.99E+307,B10:H10) -> 80 | K10: =J10-I10 -> 29 | L10: =MAX(B10:H10) -> 86
A11: 이시원 | B11: 62 | C11: 61 | D11: 69 | E11: 78 | F11: 73 | G11: 71 | H11: 77 | I11: =B11 -> 62 | J11: =LOOKUP(9.99E+307,B11:H11) -> 77 | K11: =J11-I11 -> 15 | L11: =MAX(B11:H11) -> 78
A12: 평균 | B12: =IF(COUNT(B6:B11)=0,"",AVERAGE(B6:B11)) -> 65 | C12: =IF(COUNT(C6:C11)=0,"",AVERAGE(C6:C11)) -> 73.166667 | D12: =IF(COUNT(D6:D11)=0,"",AVERAGE(D6:D11)) -> 73.833333 | E12: =IF(COUNT(E6:E11)=0,"",AVERAGE(E6:E11)) -> 81.333333 | F12: =IF(COUNT(F6:F11)=0,"",AVERAGE(F6:F11)) -> 79 | G12: =IF(COUNT(G6:G11)=0,"",AVERAGE(G6:G11)) -> 79.166667 | H12: =IF(COUNT(H6:H11)=0,"",AVERAGE(H6:H11)) -> 81.166667
A14: 등급
A15: 학생 | B15: 중1 1차 고1 | C15: 중1 2차 고1 | D15: 중1 3차 고1 | E15: 중1 4차 고1 | F15: 중2 1차 고1 | G15: 중2 2차 고1 | H15: 중2 3차 고2
A16: 김지수 | B16: 4 | C16: 4 | D16: 4 | E16: 4 | F16: 4 | G16: 3 | H16: 3
A17: 김채율 | B17: 5 | C17: 2 | D17: 3 | E17: 3 | F17: 2 | G17: 3 | H17: 3
A18: 이서연 | B18: 2 | C18: 1 | D18: 1 | E18: 1 | F18: 2 | G18: 1 | H18: 1
A19: 황재성 | B19: 4 | C19: 3 | D19: 3 | E19: 1 | F19: 2 | G19: 3 | H19: 2
A20: 서예준 | B20: 5 | C20: 5 | D20: 4 | E20: 2 | F20: 3 | G20: 2 | H20: 2
A21: 이시원 | B21: 4 | C21: 4 | D21: 4 | E21: 3 | F21: 3 | G21: 3 | H21: 3
A23: 듣기 (맞은 개수 / 17)
A24: 학생 | B24: 중1 1차 고1 | C24: 중1 2차 고1 | D24: 중1 3차 고1 | E24: 중1 4차 고1 | F24: 중2 1차 고1 | G24: 중2 2차 고1 | H24: 중2 3차 고2
A25: 김지수 | B25: 14 | D25: 16 | E25: 16 | F25: 15 | G25: 16 | H25: 17
A26: 김채율 | B26: 17 | D26: 17 | E26: 15 | F26: 17 | G26: 17 | H26: 16
A27: 이서연 | B27: 17 | D27: 17 | E27: 17 | F27: 17 | G27: 17 | H27: 17
A28: 황재성 | B28: 15 | D28: 15 | E28: 17 | F28: 17 | G28: 15 | H28: 17
A29: 서예준 | B29: 16 | D29: 16 | E29: 16 | F29: 17 | G29: 17 | H29: 17
A30: 이시원 | D30: 16 | E30: 17 | F30: 17 | G30: 16 | H30: 17
A31: 평균 | B31: =IF(COUNT(B25:B30)=0,"",AVERAGE(B25:B30)) -> 15.8 | C31: =IF(COUNT(C25:C30)=0,"",AVERAGE(C25:C30)) | D31: =IF(COUNT(D25:D30)=0,"",AVERAGE(D25:D30)) -> 16.166667 | E31: =IF(COUNT(E25:E30)=0,"",AVERAGE(E25:E30)) -> 16.333333 | F31: =IF(COUNT(F25:F30)=0,"",AVERAGE(F25:F30)) -> 16.666667 | G31: =IF(COUNT(G25:G30)=0,"",AVERAGE(G25:G30)) -> 16.333333 | H31: =IF(COUNT(H25:H30)=0,"",AVERAGE(H25:H30)) -> 16.833333
A33: 독해 (맞은 개수 / 28)
A34: 학생 | B34: 중1 1차 고1 | C34: 중1 2차 고1 | D34: 중1 3차 고1 | E34: 중1 4차 고1 | F34: 중2 1차 고1 | G34: 중2 2차 고1 | H34: 중2 3차 고2
A35: 김지수 | B35: 16 | D35: 16 | E35: 13 | F35: 16 | G35: 18 | H35: 19
A36: 김채율 | B36: 11 | D36: 18 | E36: 21 | F36: 23 | G36: 17 | H36: 19
A37: 이서연 | B37: 23 | D37: 24 | E37: 26 | F37: 23 | G37: 28 | H37: 26
A38: 황재성 | B38: 17 | D38: 18 | E38: 24 | F38: 24 | G38: 20 | H38: 21
A39: 서예준 | B39: 8 | D39: 16 | E39: 23 | F39: 18 | G39: 21 | H39: 20
A40: 이시원 | D40: 16 | E40: 19 | F40: 17 | G40: 18 | H40: 19
A41: 평균 | B41: =IF(COUNT(B35:B40)=0,"",AVERAGE(B35:B40)) -> 15 | C41: =IF(COUNT(C35:C40)=0,"",AVERAGE(C35:C40)) | D41: =IF(COUNT(D35:D40)=0,"",AVERAGE(D35:D40)) -> 18 | E41: =IF(COUNT(E35:E40)=0,"",AVERAGE(E35:E40)) -> 21 | F41: =IF(COUNT(F35:F40)=0,"",AVERAGE(F35:F40)) -> 20.166667 | G41: =IF(COUNT(G35:G40)=0,"",AVERAGE(G35:G40)) -> 20.333333 | H41: =IF(COUNT(H35:H40)=0,"",AVERAGE(H35:H40)) -> 20.666667
A43: 학교 내신 (영어)
A44: 학생 | B44: 중1 (2025) 2학기 중간 | C44: 중2 (2026) 1학기 중간 | D44: 중2 (2026) 1학기 기말 | E44: 중2 (2026) 2학기 중간 | F44: 평균
A45: 김지수 | B45: 97 | C45: 100 | D45: 97 | E45: 100 | F45: =IF(COUNT(B45:E45)=0,"",AVERAGE(B45:E45)) -> 98.5
...
